<?xml version="1.0" ?>
<!-- =================================================================================== -->
<!-- |    This document was autogenerated by xacro from spot.xacro                     | -->
<!-- |    EDITING THIS FILE BY HAND IS NOT RECOMMENDED                                 | -->
<!-- =================================================================================== -->
<robot name="spot">
  <link name="body">
    <visual>
      <geometry>
        <mesh filename="../meshes/body.dae"/>
      </geometry>
    </visual>
    <collision>
      <geometry>
        <mesh filename="../meshes/body_collision.stl"/>
      </geometry>
    </collision>
  </link>
  <link name="base_link"/>
  <joint name="base_link_joint" type="fixed">
    <origin rpy="0 0 0" xyz="0 0 0"/>
    <parent link="body"/>
    <child link="base_link"/>
  </joint>
  <link name="front_rail"/>
  <joint name="front_rail_joint" type="fixed">
    <origin rpy="0 0 0" xyz="0.223 0 0.0805"/>
    <parent link="body"/>
    <child link="front_rail"/>
  </joint>
  <link name="rear_rail"/>
  <joint name="rear_rail_joint" type="fixed">
    <origin rpy="0 0 0" xyz="-0.223 0 0.0805"/>
    <parent link="body"/>
    <child link="rear_rail"/>
  </joint>
  <link name="front_left_hip">
    <visual>
      <geometry>
        <mesh filename="../meshes/front_left_hip.dae"/>
      </geometry>
    </visual>
    <collision>
      <geometry>
        <mesh filename="../meshes/front_left_hip_collision.stl"/>
      </geometry>
    </collision>
  </link>
  <joint name="fl_hx" type="fixed">
    <origin rpy="0 0 0" xyz="0.29785 0.05500 0.00000"/>
    <axis xyz="1 0 0"/>
    <parent link="body"/>
    <child link="front_left_hip"/>
    <limit effort="1000" lower="-0.78539816339744827899" upper="0.78539816339744827899" velocity="1000.00"/>
  </joint>
  <link name="front_left_upper_leg">
    <visual>
      <geometry>
        <mesh filename="../meshes/front_left_upper_leg.dae"/>
      </geometry>
    </visual>
    <collision>
      <geometry>
        <mesh filename="../meshes/front_left_upper_leg_collision.stl"/>
      </geometry>
    </collision>
  </link>
  <joint name="fl_hy" type="fixed">
    <origin rpy="0 0 0" xyz="0.0 0.110945 0.0"/>
    <axis xyz="0 1 0"/>
    <parent link="front_left_hip"/>
    <child link="front_left_upper_leg"/>
    <limit effort="1000" lower="-0.89884456477707963539" upper="2.2951079663725435509" velocity="1000.00"/>
  </joint>
  <link name="front_left_lower_leg">
    <visual>
      <geometry>
        <mesh filename="../meshes/front_left_lower_leg.dae"/>
      </geometry>
    </visual>
    <collision>
      <geometry>
        <mesh filename="../meshes/front_left_lower_leg_collision.stl"/>
      </geometry>
    </collision>
  </link>
  <joint name="fl_kn" type="fixed">
    <origin rpy="0 0 0" xyz="0.025 0.000 -0.3205"/>
    <axis xyz="0 1 0"/>
    <parent link="front_left_upper_leg"/>
    <child link="front_left_lower_leg"/>
    <limit effort="1000" lower="-2.7929" upper="-0.254801" velocity="1000.00"/>
  </joint>
  <link name="front_right_hip">
    <visual>
      <geometry>
        <mesh filename="../meshes/front_right_hip.dae"/>
      </geometry>
    </visual>
    <collision>
      <geometry>
        <mesh filename="../meshes/front_right_hip_collision.stl"/>
      </geometry>
    </collision>
  </link>
  <joint name="fr_hx" type="fixed">
    <origin rpy="0 0 0" xyz="0.29785 -0.05500 0.00000"/>
    <axis xyz="1 0 0"/>
    <parent link="body"/>
    <child link="front_right_hip"/>
    <limit effort="1000" lower="-0.78539816339744827899" upper="0.78539816339744827899" velocity="1000.00"/>
  </joint>
  <link name="front_right_upper_leg">
    <visual>
      <geometry>
        <mesh filename="../meshes/front_right_upper_leg.dae"/>
      </geometry>
    </visual>
    <collision>
      <geometry>
        <mesh filename="../meshes/front_right_upper_leg_collision.stl"/>
      </geometry>
    </collision>
  </link>
  <joint name="fr_hy" type="fixed">
    <origin rpy="0 0 0" xyz="0.0 -0.110945 0.0"/>
    <axis xyz="0 1 0"/>
    <parent link="front_right_hip"/>
    <child link="front_right_upper_leg"/>
    <limit effort="1000" lower="-0.89884456477707963539" upper="2.2951079663725435509" velocity="1000.00"/>
  </joint>
  <link name="front_right_lower_leg">
    <visual>
      <geometry>
        <mesh filename="../meshes/front_right_lower_leg.dae"/>
      </geometry>
    </visual>
    <collision>
      <geometry>
        <mesh filename="../meshes/front_right_lower_leg_collision.stl"/>
      </geometry>
    </collision>
  </link>
  <joint name="fr_kn" type="fixed">
    <origin rpy="0 0 0" xyz="0.025 0.000 -0.3205"/>
    <axis xyz="0 1 0"/>
    <parent link="front_right_upper_leg"/>
    <child link="front_right_lower_leg"/>
    <limit effort="1000" lower="-2.7929" upper="-0.247563" velocity="1000.00"/>
  </joint>
  <link name="rear_left_hip">
    <visual>
      <geometry>
        <mesh filename="../meshes/rear_left_hip.dae"/>
      </geometry>
    </visual>
    <collision>
      <geometry>
        <mesh filename="../meshes/rear_left_hip_collision.stl"/>
      </geometry>
    </collision>
  </link>
  <joint name="hl_hx" type="fixed">
    <origin rpy="0 0 0" xyz="-0.29785 0.05500 0.00000"/>
    <axis xyz="1 0 0"/>
    <parent link="body"/>
    <child link="rear_left_hip"/>
    <limit effort="1000" lower="-0.78539816339744827899" upper="0.78539816339744827899" velocity="1000.00"/>
  </joint>
  <link name="rear_left_upper_leg">
    <visual>
      <geometry>
        <mesh filename="../meshes/rear_left_upper_leg.dae"/>
      </geometry>
    </visual>
    <collision>
      <geometry>
        <mesh filename="../meshes/rear_left_upper_leg_collision.stl"/>
      </geometry>
    </collision>
  </link>
  <joint name="hl_hy" type="fixed">
    <origin rpy="0 0 0" xyz="0.0 0.110945 0.0"/>
    <axis xyz="0 1 0"/>
    <parent link="rear_left_hip"/>
    <child link="rear_left_upper_leg"/>
    <limit effort="1000" lower="-0.89884456477707963539" upper="2.2951079663725435509" velocity="1000.00"/>
  </joint>
  <link name="rear_left_lower_leg">
    <visual>
      <geometry>
        <mesh filename="../meshes/rear_left_lower_leg.dae"/>
      </geometry>
    </visual>
    <collision>
      <geometry>
        <mesh filename="../meshes/rear_left_lower_leg_collision.stl"/>
      </geometry>
    </collision>
  </link>
  <joint name="hl_kn" type="fixed">
    <origin rpy="0 0 0" xyz="0.025 0.000 -0.3205"/>
    <axis xyz="0 1 0"/>
    <parent link="rear_left_upper_leg"/>
    <child link="rear_left_lower_leg"/>
    <limit effort="1000" lower="-2.7929" upper="-0.267153" velocity="1000.00"/>
  </joint>
  <link name="rear_right_hip">
    <visual>
      <geometry>
        <mesh filename="../meshes/rear_right_hip.dae"/>
      </geometry>
    </visual>
    <collision>
      <geometry>
        <mesh filename="../meshes/rear_right_hip_collision.stl"/>
      </geometry>
    </collision>
  </link>
  <joint name="hr_hx" type="fixed">
    <origin rpy="0 0 0" xyz="-0.29785 -0.05500 0.00000"/>
    <axis xyz="1 0 0"/>
    <parent link="body"/>
    <child link="rear_right_hip"/>
    <limit effort="1000" lower="-0.78539816339744827899" upper="0.78539816339744827899" velocity="1000.00"/>
  </joint>
  <link name="rear_right_upper_leg">
    <visual>
      <geometry>
        <mesh filename="../meshes/rear_right_upper_leg.dae"/>
      </geometry>
    </visual>
    <collision>
      <geometry>
        <mesh filename="../meshes/rear_right_upper_leg_collision.stl"/>
      </geometry>
    </collision>
  </link>
  <joint name="hr_hy" type="fixed">
    <origin rpy="0 0 0" xyz="0.0 -0.110945 0.0"/>
    <axis xyz="0 1 0"/>
    <parent link="rear_right_hip"/>
    <child link="rear_right_upper_leg"/>
    <limit effort="1000" lower="-0.89884456477707963539" upper="2.2951079663725435509" velocity="1000.00"/>
  </joint>
  <link name="rear_right_lower_leg">
    <visual>
      <geometry>
        <mesh filename="../meshes/rear_right_lower_leg.dae"/>
      </geometry>
    </visual>
    <collision>
      <geometry>
        <mesh filename="../meshes/rear_right_lower_leg_collision.stl"/>
      </geometry>
    </collision>
  </link>
  <joint name="hr_kn" type="fixed">
    <origin rpy="0 0 0" xyz="0.025 0.000 -0.3205"/>
    <axis xyz="0 1 0"/>
    <parent link="rear_right_upper_leg"/>
    <child link="rear_right_lower_leg"/>
    <limit effort="1000" lower="-2.7929" upper="-0.257725" velocity="1000.00"/>
  </joint>
  <link name="arm0_link_sh0">
    <visual>
      <origin rpy="0 0 0" xyz="0 0 0"/>
      <geometry>
        <mesh filename="../meshes/arm0_link_sh0.obj"/>
      </geometry>
      <material name="arm0_link_sh0">
        <color rgba="0.2 0.2 0.2 1"/>
      </material>
    </visual>
  </link>
  <joint name="arm0_sh0" type="revolute">
    <origin rpy="0 0 0" xyz="0.292 0.0 0.188"/>
    <axis xyz="0 0 1"/>
    <parent link="base_link"/>
    <child link="arm0_link_sh0"/>
    <limit effort="1000" lower="-2.61799387799149441136" upper="3.14159265358979311599" velocity="1000.00"/>
  </joint>
  <link name="arm0_link_sh1">
    <visual>
      <origin rpy="0 0 0" xyz="0 0 0"/>
      <geometry>
        <mesh filename="../meshes/arm0_link_sh1.obj"/>
      </geometry>
      <material name="arm0_link_sh1">
        <color rgba="0.2 0.2 0.2 1"/>
      </material>
    </visual>
  </link>
  <joint name="arm0_sh1" type="revolute">
    <origin rpy="0 0 0" xyz="0.0 0.0 0.0"/>
    <axis xyz="0 1 0"/>
    <parent link="arm0_link_sh0"/>
    <child link="arm0_link_sh1"/>
    <limit effort="1000" lower="-3.14159265358979311599" upper="0.52359877559829881565" velocity="1000.00"/>
  </joint>
  <link name="arm0_link_hr0">
    <visual>
      <origin rpy="0 0 0" xyz="0 0 0"/>
      <geometry>
        <mesh filename="../meshes/arm0_link_hr0.obj"/>
      </geometry>
      <material name="arm0_link_hr0">
        <color rgba="0.2 0.2 0.2 1"/>
      </material>
    </visual>
  </link>
  <joint name="arm0_hr0" type="revolute">
    <origin rpy="0 0 0" xyz="0.0 0.0 0.0"/>
    <axis xyz="1 0 0"/>
    <parent link="arm0_link_sh1"/>
    <child link="arm0_link_hr0"/>
    <limit effort="1000" lower="-1e6" upper="1e6" velocity="1000.00"/>
  </joint>
  <link name="arm0_link_el0">
    <visual>
      <origin rpy="0 0 0" xyz="0 0 0"/>
      <geometry>
        <mesh filename="../meshes/arm0_link_el0.obj"/>
      </geometry>
      <material name="arm0_link_el0">
        <color rgba="0.2 0.2 0.2 1"/>
      </material>
    </visual>
  </link>
  <joint name="arm0_el0" type="revolute">
    <origin rpy="0 0 0" xyz="0.3385 0 0"/>
    <axis xyz="0 1 0"/>
    <parent link="arm0_link_hr0"/>
    <child link="arm0_link_el0"/>
    <limit effort="1000" lower="0" upper="3.14159265358979311599" velocity="1000.00"/>
  </joint>
  <link name="arm0_link_el1">
    <visual>
      <origin rpy="0 0 0" xyz="0 0 0"/>
      <geometry>
        <mesh filename="../meshes/arm0_link_el1.obj"/>
      </geometry>
      <material name="arm0_link_el1">
        <color rgba="0.2 0.2 0.2 1"/>
      </material>
    </visual>
  </link>
  <joint name="arm0_el1" type="revolute">
    <origin rpy="0 0 0" xyz="0.40330 0.0 0.0750"/>
    <axis xyz="1 0 0"/>
    <parent link="arm0_link_el0"/>
    <child link="arm0_link_el1"/>
    <limit effort="1000" lower="-2.79252680319092716487" upper="2.79252680319092716487" velocity="1000.00"/>
  </joint>
  <link name="arm0_link_wr0">
    <visual>
      <origin rpy="0 0 0" xyz="0 0 0"/>
      <geometry>
        <mesh filename="../meshes/arm0_link_wr0.obj"/>
      </geometry>
      <material name="arm0_link_wr0">
        <color rgba="0.2 0.2 0.2 1"/>
      </material>
    </visual>
  </link>
  <joint name="arm0_wr0" type="revolute">
    <origin rpy="0 0 0" xyz="0.0 0.0 0.0"/>
    <axis xyz="0 1 0"/>
    <parent link="arm0_link_el1"/>
    <child link="arm0_link_wr0"/>
    <limit effort="1000" lower="-1.83259571459404613236" upper="1.83259571459404613236" velocity="1000.00"/>
  </joint>
  <link name="arm0_link_wr1">
    <visual>
      <origin rpy="0 0 0" xyz="0 0 0"/>
      <geometry>
        <mesh filename="../meshes/arm0_link_wr1.obj"/>
      </geometry>
      <material name="arm0_link_wr1">
        <color rgba="0.2 0.2 0.2 1"/>
      </material>
    </visual>
  </link>
  <joint name="arm0_wr1" type="revolute">
    <origin rpy="0 0 0" xyz="0.0 0.0 0.0"/>
    <axis xyz="1 0 0"/>
    <parent link="arm0_link_wr0"/>
    <child link="arm0_link_wr1"/>
    <limit effort="1000" lower="-2.87979326579064354163" upper="2.87979326579064354163" velocity="1000.00"/>
  </joint>
  <link name="arm0_link_fngr">
    <visual>
      <origin rpy="0 0 0" xyz="0 0 0"/>
      <geometry>
        <mesh filename="../meshes/arm0_link_fngr.obj"/>
      </geometry>
      <material name="arm0_link_fngr">
        <color rgba="0.2 0.2 0.2 1"/>
      </material>
    </visual>
  </link>
  <joint name="arm0_f1x" type="revolute">
    <origin rpy="0 0 0" xyz="0.11745 0 0.014820"/>
    <axis xyz="0.0 1.0 0.0"/>
    <parent link="arm0_link_wr1"/>
    <child link="arm0_link_fngr"/>
    <limit effort="1000" lower="-1.57" upper="0.0" velocity="1000.00"/>
  </joint>
  <link name="arm0_link_ee"/>
  <joint name="arm0_ee_joint" type="fixed">
    <origin rpy="0 0 0" xyz="0.13 0.0 -0.06"/>
    <parent link="arm0_link_fngr"/>
    <child link="arm0_link_ee"/>
  </joint>
  <!-- This file is a placeholder which is included by default from
       spot.urdf.xacro. If a robot is being customized and requires
       additional URDF, set the SPOT_URDF_EXTRAS environment variable
       to the full path of the file you would like included. -->
</robot>

